2023-10-07 15:20:31,328 INFO [streaming_server.py:808] {'encoder': './sherpa-onnx-streaming-zipformer-en-2023-06-21/encoder-epoch-99-avg-1.int8.onnx', 'decoder': './sherpa-onnx-streaming-zipformer-en-2023-06-21/decoder-epoch-99-avg-1.int8.onnx', 'joiner': './sherpa-onnx-streaming-zipformer-en-2023-06-21/joiner-epoch-99-avg-1.int8.onnx', 'paraformer_encoder': None, 'paraformer_decoder': None, 'tokens': './sherpa-onnx-streaming-zipformer-en-2023-06-21/tokens.txt', 'sample_rate': 16000, 'feat_dim': 80, 'provider': 'cpu', 'decoding_method': 'greedy_search', 'num_active_paths': 4, 'use_endpoint': 1, 'rule1_min_trailing_silence': 2.4, 'rule2_min_trailing_silence': 1.2, 'rule3_min_utterance_length': 20, 'hotwords_file': '', 'hotwords_score': 1.5, 'port': 6006, 'nn_pool_size': 1, 'max_batch_size': 50, 'max_wait_ms': 10, 'max_message_size': 1048576, 'max_queue_size': 32, 'max_active_connections': 500, 'num_threads': 2, 'certificate': None, 'doc_root': 'web'}
2023-10-07 15:20:33,272 INFO [streaming_server.py:625] No certificate provided
2023-10-07 15:20:33,273 INFO [server.py:711] server listening on 0.0.0.0:6006
2023-10-07 15:20:33,274 INFO [server.py:711] server listening on [::]:6006
2023-10-07 15:20:33,274 INFO [streaming_server.py:651] Please visit one of the following addresses:

  http://localhost:6006

Since you are not providing a certificate, you cannot use your microphone from within the browser using public IP addresses. Only localhost can be used.You also cannot use 0.0.0.0 or 127.0.0.1
2023-10-07 15:20:41,261 INFO [server.py:233] connection failed (200 OK)
2023-10-07 15:20:41,263 INFO [server.py:268] connection closed
2023-10-07 15:20:41,334 INFO [server.py:233] connection failed (200 OK)
2023-10-07 15:20:41,334 INFO [server.py:268] connection closed
2023-10-07 15:20:41,337 INFO [server.py:233] connection failed (200 OK)
2023-10-07 15:20:41,337 INFO [server.py:233] connection failed (200 OK)
2023-10-07 15:20:41,338 INFO [server.py:233] connection failed (200 OK)
2023-10-07 15:20:41,338 INFO [server.py:233] connection failed (200 OK)
2023-10-07 15:20:41,338 INFO [server.py:268] connection closed
2023-10-07 15:20:41,338 INFO [server.py:268] connection closed
2023-10-07 15:20:41,339 INFO [server.py:268] connection closed
2023-10-07 15:20:41,339 INFO [server.py:268] connection closed
2023-10-07 15:20:41,397 INFO [server.py:233] connection failed (200 OK)
2023-10-07 15:20:41,398 INFO [server.py:268] connection closed
2023-10-07 15:20:41,399 INFO [server.py:233] connection failed (200 OK)
2023-10-07 15:20:41,400 INFO [server.py:233] connection failed (200 OK)
2023-10-07 15:20:41,401 INFO [server.py:233] connection failed (200 OK)
2023-10-07 15:20:41,401 INFO [server.py:268] connection closed
2023-10-07 15:20:41,401 INFO [server.py:268] connection closed
2023-10-07 15:20:41,402 INFO [server.py:268] connection closed
2023-10-07 15:20:42,700 INFO [server.py:646] connection open
2023-10-07 15:20:42,700 INFO [streaming_server.py:692] Connected: ('::1', 54064, 0, 0). Number of connections: 1/500
2023-10-07 15:22:01,945 INFO [streaming_server.py:676] Disconnected: ('::1', 54064, 0, 0). Number of connections: 0/500
2023-10-07 15:22:01,947 ERROR [server.py:242] connection handler failed
Traceback (most recent call last):
  File "/Library/Frameworks/Python.framework/Versions/3.11/lib/python3.11/site-packages/urllib3/connectionpool.py", line 536, in _make_request
    response = conn.getresponse()
               ^^^^^^^^^^^^^^^^^^
  File "/Library/Frameworks/Python.framework/Versions/3.11/lib/python3.11/site-packages/urllib3/connection.py", line 461, in getresponse
    httplib_response = super().getresponse()
                       ^^^^^^^^^^^^^^^^^^^^^
  File "/Library/Frameworks/Python.framework/Versions/3.11/lib/python3.11/http/client.py", line 1378, in getresponse
    response.begin()
  File "/Library/Frameworks/Python.framework/Versions/3.11/lib/python3.11/http/client.py", line 318, in begin
    version, status, reason = self._read_status()
                              ^^^^^^^^^^^^^^^^^^^
  File "/Library/Frameworks/Python.framework/Versions/3.11/lib/python3.11/http/client.py", line 279, in _read_status
    line = str(self.fp.readline(_MAXLINE + 1), "iso-8859-1")
               ^^^^^^^^^^^^^^^^^^^^^^^^^^^^^^
  File "/Library/Frameworks/Python.framework/Versions/3.11/lib/python3.11/socket.py", line 706, in readinto
    return self._sock.recv_into(b)
           ^^^^^^^^^^^^^^^^^^^^^^^
  File "/Library/Frameworks/Python.framework/Versions/3.11/lib/python3.11/ssl.py", line 1278, in recv_into
    return self.read(nbytes, buffer)
           ^^^^^^^^^^^^^^^^^^^^^^^^^
  File "/Library/Frameworks/Python.framework/Versions/3.11/lib/python3.11/ssl.py", line 1134, in read
    return self._sslobj.read(len, buffer)
           ^^^^^^^^^^^^^^^^^^^^^^^^^^^^^^
TimeoutError: The read operation timed out

The above exception was the direct cause of the following exception:

Traceback (most recent call last):
  File "/Library/Frameworks/Python.framework/Versions/3.11/lib/python3.11/site-packages/requests/adapters.py", line 486, in send
    resp = conn.urlopen(
           ^^^^^^^^^^^^^
  File "/Library/Frameworks/Python.framework/Versions/3.11/lib/python3.11/site-packages/urllib3/connectionpool.py", line 844, in urlopen
    retries = retries.increment(
              ^^^^^^^^^^^^^^^^^^
  File "/Library/Frameworks/Python.framework/Versions/3.11/lib/python3.11/site-packages/urllib3/util/retry.py", line 470, in increment
    raise reraise(type(error), error, _stacktrace)
          ^^^^^^^^^^^^^^^^^^^^^^^^^^^^^^^^^^^^^^^^
  File "/Library/Frameworks/Python.framework/Versions/3.11/lib/python3.11/site-packages/urllib3/util/util.py", line 39, in reraise
    raise value
  File "/Library/Frameworks/Python.framework/Versions/3.11/lib/python3.11/site-packages/urllib3/connectionpool.py", line 790, in urlopen
    response = self._make_request(
               ^^^^^^^^^^^^^^^^^^^
  File "/Library/Frameworks/Python.framework/Versions/3.11/lib/python3.11/site-packages/urllib3/connectionpool.py", line 538, in _make_request
    self._raise_timeout(err=e, url=url, timeout_value=read_timeout)
  File "/Library/Frameworks/Python.framework/Versions/3.11/lib/python3.11/site-packages/urllib3/connectionpool.py", line 370, in _raise_timeout
    raise ReadTimeoutError(
urllib3.exceptions.ReadTimeoutError: HTTPSConnectionPool(host='api-inference.huggingface.co', port=443): Read timed out. (read timeout=30.0)

During handling of the above exception, another exception occurred:

Traceback (most recent call last):
  File "/Library/Frameworks/Python.framework/Versions/3.11/lib/python3.11/site-packages/websockets/legacy/server.py", line 240, in handler
    await self.ws_handler(self)
  File "/Users/fawazahamedshaik/github/ASR/Interactive_ASR/./streaming_server.py", line 669, in handle_connection
    await self.handle_connection_impl(socket)
  File "/Users/fawazahamedshaik/github/ASR/Interactive_ASR/./streaming_server.py", line 724, in handle_connection_impl
    text = generate(message['text'])
           ^^^^^^^^^^^^^^^^^^^^^^^^^
  File "/Users/fawazahamedshaik/github/ASR/Interactive_ASR/./streaming_server.py", line 104, in generate
    out=pn(f"""{result}""")
        ^^^^^^^^^^^^^^^^^^^
  File "/Library/Frameworks/Python.framework/Versions/3.11/lib/python3.11/site-packages/haystack/nodes/prompt/prompt_node.py", line 140, in __call__
    return self.prompt(self.default_prompt_template, *args, **kwargs)
           ^^^^^^^^^^^^^^^^^^^^^^^^^^^^^^^^^^^^^^^^^^^^^^^^^^^^^^^^^^
  File "/Library/Frameworks/Python.framework/Versions/3.11/lib/python3.11/site-packages/haystack/nodes/prompt/prompt_node.py", line 179, in prompt
    output = self.prompt_model.invoke(prompt, **kwargs_copy)
             ^^^^^^^^^^^^^^^^^^^^^^^^^^^^^^^^^^^^^^^^^^^^^^^
  File "/Library/Frameworks/Python.framework/Versions/3.11/lib/python3.11/site-packages/haystack/nodes/prompt/prompt_model.py", line 111, in invoke
    output = self.model_invocation_layer.invoke(prompt=prompt, **kwargs)
             ^^^^^^^^^^^^^^^^^^^^^^^^^^^^^^^^^^^^^^^^^^^^^^^^^^^^^^^^^^^
  File "/Library/Frameworks/Python.framework/Versions/3.11/lib/python3.11/site-packages/haystack/nodes/prompt/invocation_layer/hugging_face_inference.py", line 173, in invoke
    response: requests.Response = self._post(
                                  ^^^^^^^^^^^
  File "/Library/Frameworks/Python.framework/Versions/3.11/lib/python3.11/site-packages/haystack/nodes/prompt/invocation_layer/hugging_face_inference.py", line 237, in _post
    response = request_with_retry(
               ^^^^^^^^^^^^^^^^^^^
  File "/Library/Frameworks/Python.framework/Versions/3.11/lib/python3.11/site-packages/haystack/utils/requests_utils.py", line 90, in request_with_retry
    res = run()
          ^^^^^
  File "/Library/Frameworks/Python.framework/Versions/3.11/lib/python3.11/site-packages/tenacity/__init__.py", line 289, in wrapped_f
    return self(f, *args, **kw)
           ^^^^^^^^^^^^^^^^^^^^
  File "/Library/Frameworks/Python.framework/Versions/3.11/lib/python3.11/site-packages/tenacity/__init__.py", line 379, in __call__
    do = self.iter(retry_state=retry_state)
         ^^^^^^^^^^^^^^^^^^^^^^^^^^^^^^^^^^
  File "/Library/Frameworks/Python.framework/Versions/3.11/lib/python3.11/site-packages/tenacity/__init__.py", line 314, in iter
    return fut.result()
           ^^^^^^^^^^^^
  File "/Library/Frameworks/Python.framework/Versions/3.11/lib/python3.11/concurrent/futures/_base.py", line 449, in result
    return self.__get_result()
           ^^^^^^^^^^^^^^^^^^^
  File "/Library/Frameworks/Python.framework/Versions/3.11/lib/python3.11/concurrent/futures/_base.py", line 401, in __get_result
    raise self._exception
  File "/Library/Frameworks/Python.framework/Versions/3.11/lib/python3.11/site-packages/tenacity/__init__.py", line 382, in __call__
    result = fn(*args, **kwargs)
             ^^^^^^^^^^^^^^^^^^^
  File "/Library/Frameworks/Python.framework/Versions/3.11/lib/python3.11/site-packages/haystack/utils/requests_utils.py", line 82, in run
    res = requests.request(**kwargs, timeout=timeout)
          ^^^^^^^^^^^^^^^^^^^^^^^^^^^^^^^^^^^^^^^^^^^
  File "/Library/Frameworks/Python.framework/Versions/3.11/lib/python3.11/site-packages/requests/api.py", line 59, in request
    return session.request(method=method, url=url, **kwargs)
           ^^^^^^^^^^^^^^^^^^^^^^^^^^^^^^^^^^^^^^^^^^^^^^^^^
  File "/Library/Frameworks/Python.framework/Versions/3.11/lib/python3.11/site-packages/requests/sessions.py", line 589, in request
    resp = self.send(prep, **send_kwargs)
           ^^^^^^^^^^^^^^^^^^^^^^^^^^^^^^
  File "/Library/Frameworks/Python.framework/Versions/3.11/lib/python3.11/site-packages/requests/sessions.py", line 703, in send
    r = adapter.send(request, **kwargs)
        ^^^^^^^^^^^^^^^^^^^^^^^^^^^^^^^
  File "/Library/Frameworks/Python.framework/Versions/3.11/lib/python3.11/site-packages/requests/adapters.py", line 532, in send
    raise ReadTimeout(e, request=request)
requests.exceptions.ReadTimeout: HTTPSConnectionPool(host='api-inference.huggingface.co', port=443): Read timed out. (read timeout=30.0)
2023-10-07 15:22:01,978 INFO [server.py:268] connection closed
2023-10-07 15:22:09,961 INFO [server.py:233] connection failed (200 OK)
2023-10-07 15:22:09,961 INFO [server.py:268] connection closed
2023-10-07 15:22:10,014 INFO [server.py:233] connection failed (200 OK)
2023-10-07 15:22:10,024 INFO [server.py:268] connection closed
2023-10-07 15:22:10,025 INFO [server.py:233] connection failed (200 OK)
2023-10-07 15:22:10,025 INFO [server.py:233] connection failed (200 OK)
2023-10-07 15:22:10,026 INFO [server.py:233] connection failed (200 OK)
2023-10-07 15:22:10,026 INFO [server.py:233] connection failed (200 OK)
2023-10-07 15:22:10,026 INFO [server.py:268] connection closed
2023-10-07 15:22:10,026 INFO [server.py:268] connection closed
2023-10-07 15:22:10,026 INFO [server.py:268] connection closed
2023-10-07 15:22:10,026 INFO [server.py:268] connection closed
2023-10-07 15:22:10,036 INFO [server.py:233] connection failed (200 OK)
2023-10-07 15:22:10,036 INFO [server.py:268] connection closed
2023-10-07 15:22:10,053 INFO [server.py:233] connection failed (200 OK)
2023-10-07 15:22:10,055 INFO [server.py:233] connection failed (200 OK)
2023-10-07 15:22:10,057 INFO [server.py:268] connection closed
2023-10-07 15:22:10,059 INFO [server.py:268] connection closed
2023-10-07 15:22:10,073 INFO [server.py:233] connection failed (200 OK)
2023-10-07 15:22:10,074 INFO [server.py:268] connection closed
2023-10-07 15:22:12,179 INFO [server.py:646] connection open
2023-10-07 15:22:12,179 INFO [streaming_server.py:692] Connected: ('::1', 54444, 0, 0). Number of connections: 1/500
